Unhandled exception in thread started by <function check_errors.<locals>.wrapper at 0x7f3669b19ae8>
Traceback (most recent call last):
  File "/home/circ/.local/lib/python3.6/site-packages/django/utils/autoreload.py", line 225, in wrapper
    fn(*args, **kwargs)
  File "/home/circ/.local/lib/python3.6/site-packages/django/core/management/commands/runserver.py", line 117, in inner_run
    self.check(display_num_errors=True)
  File "/home/circ/.local/lib/python3.6/site-packages/django/core/management/base.py", line 379, in check
    include_deployment_checks=include_deployment_checks,
  File "/home/circ/.local/lib/python3.6/site-packages/django/core/management/base.py", line 366, in _run_checks
    return checks.run_checks(**kwargs)
  File "/home/circ/.local/lib/python3.6/site-packages/django/core/checks/registry.py", line 71, in run_checks
    new_errors = check(app_configs=app_configs)
  File "/home/circ/.local/lib/python3.6/site-packages/django/core/checks/urls.py", line 13, in check_url_config
    return check_resolver(resolver)
  File "/home/circ/.local/lib/python3.6/site-packages/django/core/checks/urls.py", line 23, in check_resolver
    return check_method()
  File "/home/circ/.local/lib/python3.6/site-packages/django/urls/resolvers.py", line 396, in check
    for pattern in self.url_patterns:
  File "/home/circ/.local/lib/python3.6/site-packages/django/utils/functional.py", line 37, in __get__
    res = instance.__dict__[self.name] = self.func(instance)
  File "/home/circ/.local/lib/python3.6/site-packages/django/urls/resolvers.py", line 533, in url_patterns
    patterns = getattr(self.urlconf_module, "urlpatterns", self.urlconf_module)
  File "/home/circ/.local/lib/python3.6/site-packages/django/utils/functional.py", line 37, in __get__
    res = instance.__dict__[self.name] = self.func(instance)
  File "/home/circ/.local/lib/python3.6/site-packages/django/urls/resolvers.py", line 526, in urlconf_module
    return import_module(self.urlconf_name)
  File "/usr/lib/python3.6/importlib/__init__.py", line 126, in import_module
    return _bootstrap._gcd_import(name[level:], package, level)
  File "<frozen importlib._bootstrap>", line 994, in _gcd_import
  File "<frozen importlib._bootstrap>", line 971, in _find_and_load
  File "<frozen importlib._bootstrap>", line 955, in _find_and_load_unlocked
  File "<frozen importlib._bootstrap>", line 665, in _load_unlocked
  File "<frozen importlib._bootstrap_external>", line 678, in exec_module
  File "<frozen importlib._bootstrap>", line 219, in _call_with_frames_removed
  File "/home/circ/circDraw/cirDraw/cirDraw/urls.py", line 21, in <module>
    from tools import views as toolviews
  File "/home/circ/circDraw/cirDraw/tools/views.py", line 11, in <module>
    from .handle_file import handle
  File "/home/circ/circDraw/cirDraw/tools/handle_file.py", line 171
    print("Before try": l)
                      ^
SyntaxError: invalid syntax
Performing system checks...

origin:  <django.forms.fields.CharField object at 0x7f366924e898>
